<?xml version="1.0"?>
<robot name="claying_shovel_env">
  <material name="block_gray">
    <color rgba="0.6 0.6 0.6 0.8" />
  </material>
  <material name="basin_blue">
    <color rgba="0.2 0.4 0.8 0.7" />
  </material>
  <link name="ur10">
    <visual>
      <origin xyz="0 0 0" rpy="0 0 0" />
      <geometry>
        <mesh filename="meshes/base.dae" />
      </geometry>
      <material name="SWMaterial-2_001">
        <color rgba="0.37255294 0.37255294 0.37255294 1.00000000" />
      </material>
    </visual>
    <collision>
      <origin xyz="0 0 0.019" rpy="0 0 0" />
      <geometry>
        <cylinder radius="0.075" length="0.038" />
      </geometry>
    </collision>
    <inertial>
      <origin xyz="0 0 0" rpy="0 0 0" />
      <mass value="4" />
      <inertia ixx="0.0061063" ixy="0" ixz="0" iyy="0.0061063" iyz="0" izz="0.01125" />
    </inertial>
  </link>
  <link name="ur10_shoulder">
    <visual>
      <origin xyz="0 0 0" rpy="0 0 0" />
      <geometry>
        <mesh filename="meshes/shoulder.dae" />
      </geometry>
      <material name="SWMaterial-0">
        <color rgba="0.22353333 0.22353333 0.22353333 1.00000000" />
      </material>
      <material name="SWMaterial-1">
        <color rgba="0.39216078 0.54118039 0.63921961 1.00000000" />
      </material>
      <material name="SWMaterial-2">
        <color rgba="0.46274902 0.46274902 0.46274902 1.00000000" />
      </material>
    </visual>
    <collision>
      <origin xyz="0 0 0" rpy="0 0 0" />
      <geometry>
        <cylinder radius="0.075" length="0.177" />
      </geometry>
    </collision>
    <inertial>
      <origin xyz="0 0 0" rpy="0 0 0" />
      <mass value="7.778" />
      <inertia ixx="0.0314743" ixy="0" ixz="0" iyy="0.0314743" iyz="0" izz="0.0218756" />
    </inertial>
  </link>
  <link name="ur10_upper_arm">
    <visual>
      <origin xyz="0 0 0" rpy="0 0 0" />
      <geometry>
        <mesh filename="meshes/upperarm.dae" />
      </geometry>
      <material name="SWMaterial-0">
        <color rgba="0.22353333 0.22353333 0.22353333 1.00000000" />
      </material>
      <material name="SWMaterial-1">
        <color rgba="0.39216078 0.54118039 0.63921961 1.00000000" />
      </material>
      <material name="SWMaterial-2">
        <color rgba="0.46274902 0.46274902 0.46274902 1.00000000" />
      </material>
      <material name="SWMaterial-3">
        <color rgba="0.65490588 0.65490588 0.65490588 1.00000000" />
      </material>
    </visual>
    <collision>
      <origin xyz="0 -0.045 0" rpy="1.5707 0 0" />
      <geometry>
        <cylinder radius="0.075" length="0.177" />
      </geometry>
    </collision>
    <collision>
      <origin xyz="0 -0.0436 0.32" rpy="0 0 1.5707" />
      <geometry>
        <cylinder radius="0.058" length="0.461" />
      </geometry>
    </collision>
    <collision>
      <origin xyz="0 -0.04 0.613" rpy="1.5707 0 0" />
      <geometry>
        <cylinder radius="0.058" length="0.129" />
      </geometry>
    </collision>
    <inertial>
      <origin xyz="0 0 0.306" rpy="0 0 0" />
      <mass value="12.93" />
      <inertia ixx="0.421754" ixy="0" ixz="0" iyy="0.421754" iyz="0" izz="0.0363656" />
    </inertial>
  </link>
  <link name="ur10_forearm">
    <visual>
      <origin xyz="0 0 0" rpy="0 0 0" />
      <geometry>
        <mesh filename="meshes/forearm.dae" />
      </geometry>
      <material name="SWMaterial-0">
        <color rgba="0.22353333 0.22353333 0.22353333 1.00000000" />
      </material>
      <material name="SWMaterial-1">
        <color rgba="0.39216078 0.54118039 0.63921961 1.00000000" />
      </material>
      <material name="SWMaterial-2">
        <color rgba="0.46274902 0.46274902 0.46274902 1.00000000" />
      </material>
      <material name="SWMaterial-3">
        <color rgba="0.65490588 0.65490588 0.65490588 1.00000000" />
      </material>
      <material name="SWMaterial-4">
        <color rgba="0.07843529 0.07843529 0.07843529 1.00000000" />
      </material>
    </visual>
    <collision>
      <origin xyz="0 0 0.001" rpy="1.5707 0 0" />
      <geometry>
        <cylinder radius="0.058" length="0.136" />
      </geometry>
    </collision>
    <collision>
      <origin xyz="0 0 0.305" rpy="0 0 1.5707" />
      <geometry>
        <cylinder radius="0.045" length="0.447" />
      </geometry>
    </collision>
    <collision>
      <origin xyz="0 0.001 0.5735" rpy="1.5707 0 0" />
      <geometry>
        <cylinder radius="0.045" length="0.119" />
      </geometry>
    </collision>
    <inertial>
      <origin xyz="0 0 0.28615" rpy="0 0 0" />
      <mass value="3.87" />
      <inertia ixx="0.11107" ixy="0" ixz="0" iyy="0.11107" iyz="0" izz="0.0108844" />
    </inertial>
  </link>
  <link name="ur10_wrist_1">
    <visual>
      <origin xyz="0 0 0" rpy="0 0 0" />
      <geometry>
        <mesh filename="meshes/wrist1.dae" />
      </geometry>
      <material name="SWMaterial-0_001">
        <color rgba="0.22353333 0.22353333 0.22353333 1.00000000" />
      </material>
      <material name="SWMaterial-1_001">
        <color rgba="0.39216078 0.54118039 0.63921961 1.00000000" />
      </material>
      <material name="SWMaterial-2_001">
        <color rgba="0.46274902 0.46274902 0.46274902 1.00000000" />
      </material>
    </visual>
    <collision>
      <origin xyz="0 0.115 0.0025" rpy="0 0 0" />
      <geometry>
        <cylinder radius="0.0455" length="0.119" />
      </geometry>
    </collision>
    <inertial>
      <origin xyz="0 0 0" rpy="0 0 0" />
      <mass value="1.96" />
      <inertia ixx="0.0051082" ixy="0" ixz="0" iyy="0.0051082" iyz="0" izz="0.0055125" />
    </inertial>
  </link>
  <link name="ur10_wrist_2">
    <visual>
      <origin xyz="0 0 0" rpy="0 0 0" />
      <geometry>
        <mesh filename="meshes/wrist2.dae" />
      </geometry>
      <material name="SWMaterial-0_002">
        <color rgba="0.22353333 0.22353333 0.22353333 1.00000000" />
      </material>
      <material name="SWMaterial-1_002">
        <color rgba="0.39216078 0.54118039 0.63921961 1.00000000" />
      </material>
      <material name="SWMaterial-2_002">
        <color rgba="0.46274902 0.46274902 0.46274902 1.00000000" />
      </material>
    </visual>
    <collision>
      <origin xyz="0 0.002 0.11659" rpy="1.5707 0 0" />
      <geometry>
        <cylinder radius="0.0455" length="0.119" />
      </geometry>
    </collision>
    <inertial>
      <origin xyz="0 0 0" rpy="0 0 0" />
      <mass value="1.96" />
      <inertia ixx="0.0051082" ixy="0" ixz="0" iyy="0.0051082" iyz="0" izz="0.0055125" />
    </inertial>
  </link>
  <link name="ur10_wrist_3">
    <visual>
      <origin xyz="0 0 0" rpy="0 0 0" />
      <geometry>
        <mesh filename="meshes/wrist3.dae" />
      </geometry>
      <material name="SWMaterial-2_003">
        <color rgba="0.46274902 0.46274902 0.46274902 1.00000000" />
      </material>
    </visual>
    <collision>
      <origin xyz="0 0.0765 0" rpy="1.5707 0 0" />
      <geometry>
        <cylinder radius="0.045" length="0.031" />
      </geometry>
    </collision>
    <inertial>
      <origin xyz="0 0 0" rpy="0 0 0" />
      <mass value="0.202" />
      <inertia ixx="0.0005265" ixy="0" ixz="0" iyy="0.0005265" iyz="0" izz="0.0005681" />
    </inertial>
  </link>
  <link name="base_jizuo">
    <visual>
      <origin xyz="0 0 0" rpy="0 0 0" />
      <geometry>
        <mesh filename="meshes/base_link_world_jizuo.STL" />
      </geometry>
      <material name="mat_base_jizuo">
        <color rgba="1.00000000 1.00000000 1.00000000 1.00000000" />
      </material>
    </visual>
    <collision>
      <origin xyz="0 0 0" rpy="0 0 0" />
      <geometry>
        <mesh filename="meshes/base_link_world_jizuo.STL" />
      </geometry>
    </collision>
    <inertial>
      <origin xyz="-1.8696 -0.046752 0.24794" rpy="0 0 0" />
      <mass value="1499.1" />
      <inertia ixx="1126.8" ixy="-0.036857" ixz="0.0017432" iyy="2608.5" iyz="-18.236" izz="3614.6" />
    </inertial>
  </link>
  <link name="base_jizuo_base_ur10_with_dizuo">
    <visual>
      <origin xyz="0 0 0" rpy="0 0 0" />
      <geometry>
        <mesh filename="meshes/base_ur10_with_dizuo.STL" />
      </geometry>
      <material name="mat_base_ur10_with_dizuo">
        <color rgba="1.00000000 1.00000000 1.00000000 1.00000000" />
      </material>
    </visual>
    <collision>
      <origin xyz="0 0 0" rpy="0 0 0" />
      <geometry>
        <mesh filename="meshes/base_ur10_with_dizuo.STL" />
      </geometry>
    </collision>
    <inertial>
      <origin xyz="0 0 0.005" rpy="0 0 0" />
      <mass value="0.225" />
      <inertia ixx="0.0004237" ixy="0" ixz="0" iyy="0.0004237" iyz="0" izz="0.0008437" />
    </inertial>
  </link>
  <link name="block_with_basin_frame" />
  <link name="block_basin_base_link" />
  <link name="block_basin_block">
    <visual>
      <geometry>
        <box size="1.0 1.0 0.25" />
      </geometry>
      <material name="block_gray" />
    </visual>
    <collision>
      <geometry>
        <box size="1.0 1.0 0.25" />
      </geometry>
    </collision>
  </link>
  <link name="block_basin_back_wall">
    <visual>
      <geometry>
        <box size="0.10 0.003 0.60" />
      </geometry>
      <material name="basin_blue" />
    </visual>
    <collision>
      <geometry>
        <box size="0.10 0.003 0.60" />
      </geometry>
    </collision>
  </link>
  <joint name="ur10_shoulder_pan" type="revolute">
    <parent link="ur10" />
    <child link="ur10_shoulder" />
    <origin xyz="0 0 0.1273" rpy="0 0 0" />
    <axis xyz="0 0 1" />
    <limit lower="-6.28319" upper="6.28319" effort="330" velocity="2.16" />
  </joint>
  <joint name="ur10_shoulder_lift" type="revolute">
    <parent link="ur10_shoulder" />
    <child link="ur10_upper_arm" />
    <origin xyz="0 0.220941 0" rpy="0 1.57079 0" />
    <axis xyz="0 1 0" />
    <limit lower="-6.28319" upper="6.28319" effort="330" velocity="2.16" />
  </joint>
  <joint name="ur10_elbow" type="revolute">
    <parent link="ur10_upper_arm" />
    <child link="ur10_forearm" />
    <origin xyz="-0.0000039 -0.1719 0.612" rpy="0 0 0" />
    <axis xyz="0 1 0" />
    <limit lower="-6.28319" upper="6.28319" effort="150" velocity="3.15" />
  </joint>
  <joint name="ur10_wrist_1" type="revolute">
    <parent link="ur10_forearm" />
    <child link="ur10_wrist_1" />
    <origin xyz="-0.0000036 0 0.5723" rpy="0 1.5707895 0.0000027" />
    <axis xyz="0 1 0" />
    <limit lower="-6.28319" upper="6.28319" effort="54" velocity="3.2" />
  </joint>
  <joint name="ur10_wrist_2" type="revolute">
    <parent link="ur10_wrist_1" />
    <child link="ur10_wrist_2" />
    <origin xyz="0.0000003 0.1149 0.0000003" rpy="0 0 0" />
    <axis xyz="0 0 -1" />
    <limit lower="-6.28319" upper="6.28319" effort="54" velocity="3.2" />
  </joint>
  <joint name="ur10_wrist_3" type="revolute">
    <parent link="ur10_wrist_2" />
    <child link="ur10_wrist_3" />
    <origin xyz="0 -0.0000003 0.1157" rpy="0 0 0" />
    <axis xyz="0 1 0" />
    <limit lower="-6.28319" upper="6.28319" effort="54" velocity="3.2" />
  </joint>
  <joint name="ur10_wrist_3_to_shovel_rotate_base" type="fixed">
    <parent link="ur10_wrist_3" />
    <child link="base_link" />
    <origin xyz="                                                                                                                                                                                                                                                                                                                                                                                                                                                                                                                                                                                                                                                                                                                                                                                                                                                                                                                                                                                                                                                                                                                                                                                                                                                                                                                                                                                                                                                                                                                                                                                                                                                                                                                                                                                                                                                                                                                                                                                                                                                                                                                                                                                                                                                                                                                                                                                                                                                                                                                                                                                                                                                                                                                                                                                                                                                                                                                                                                                                                                                                                                                                                                                                                                                                                                                                                                                                                                                                                                                                                                                                                                                                                                                                                                                                                                                                                                                                                                                                                                                                                                                                                                                                                                                                                                                                                                                                                                                                                                                                                                                                                                                                                                                                                                                                                                                                                                                                                                                                                                                                                                                                                                                                                                                                                                                                                                                                                                                                                                                                                                                                                                                                                                                                                                                                                                                                                                                                                                                                                                                                                                                                                                                                                                                                                                                                                                                                                                                                                                                                                                                                                                                                                                                                                                                                                                                                                                                                                                                                                                                                                                                                                                                                                                                                                                                                                                                                                                                                                                                                                                                                                                                                                                                                                                                                                                                                                                                                                                                                                                                                                                                                                                                                                                                                                                                                                                                                                                                                                                                                                                                                                                                                                                                                                                                                                                                                                                                                                                                                                                                                                                                                                                                                                                                                                                                                                                                                                                                                                                                                                                                                                                                                                                                                                                                                                                                                                                                                                                                                                                                                                                                                                                                                                                                                                                                                                                                                                                                                                                                                                                                                                                                                                                                                                                                                                                                                                                                                                                                                                                                                                                                                                                                                                                                                                                                                                                                                                                                                                                                                                                                                                                                                                                                                                                                                                                                                                                                                                                                                                                                                                                                                                                                                                                                                                                                                                                                                                                                                                                                                                                                                                                    0 0.09 0                                                                                                                                                                                                                                                                                                                                                                                                                                                                                                                                                                                                                                                                                                                                                                                                                                                                                                                                                                                                                                                                                                                                                                                                                                                                                                                                                                                                                                                                                                                                                                                                                                                                                                                                                                                                                                                                                                                                                                                                                                                                                                                                                                                                                                                                                                                                                                                                                                                                                                                                                                                                                                                                                                                                                                                                                                                                                                                                                                                                                                                                                                                                                                                                                                                                                                                                                                                                                                                                                                                                                                                                                                                                                                                                                                                                                                                                                                                                                                                                                                                                                                                                                                                                                                                                                                                                                                                                                                                                                                                                                                                                                                                                                                                                                                                                                                                                                                                                                                                                                                                                                                                                                                                                                                                                                                                                                                                                                                                                                                                                                                                                                                                                                                                                                                                                                                                                                                                                                                                                                                                                                                                                                                                                                                                                                                                                                                                                                                                                                                                                                                                                                                                                                                                                                                                                                                                                                                                                                                                                                                                                                                                                                                                                                                                                                                                                                                                                                                                                                                                                                                                                                                                                                                                                                                                                                                                                                                                                                                                                                                                                                                                                                                                                                                                                                                                                                                                                                                                                                                                                                                                                                                                                                                                                                                                                                                                                                                                                                                                                                                                                                                                                                                                                                                                                                                                                                                                                                                                                                                                                                                                                                                                                                                                                                                                                                                                                                                                                                                                                                                                                                                                                                                                                                                                                                                                                                                                                                                                                                                                                                                                                                                                                                                                                                                                                                                                                                                                                                                                                                                                                                                                                                                                                                                                                                                                                                                                                                                                                                                                                                                                                                                                                                                                                                                                                                                                                                                                                                                                                                                                                                                                                                                                                                                                                                                                                                                                                                                                                                                                                                                                                                                                                                                                                                                              " rpy="                                                                                                                                                                                                                                                                                                                                                                                                                                                                                                                                                                                                                                                                                                                                                                                                                                                                                                                                                                                                                                                                                                                                                                                                                                                                                                                                                                                                                                                                                                                                                                                                                                                                                                                                                                                                                                                                                                                                                                                                                                                                                                                                                                                                                                                                                                                                                                                                                                                                                                                                                                                                                                                                                                                                                                                                                                                                                                                                                                                                                                                                                                                                                                                                                                                                                                                                                                                                                                                                                                                                                                                                                                                                                                                                                                                                                                                                                                                                                                                                                                                                                                                                                                                                                                                                                                                                                                                                                                                                                                                                                                                                                                                                                                                                                                                                                                                                                                                                                                                                                                                                                                                                                                                                                                                                                                                                                                                                                                                                                                                                                                                                                                                                                                                                                                                                                                                                                                                                                                                                                                                                                                                                                                                                                                                                                                                                                                                                                                                                                                                                                                                                                                                                                                                                                                                                                                                                                                                                                                                                                                                                                                                                                                                                                                                                                                                                                                                                                                                                                                                                                                                                                                                                                                                                                                                                                                                                                                                                                                                                                                                                                                                                                                                                                                                                                                                                                                                                                                                                                                                                                                                                                                                                                                                                                                                                                                                                                                                                                                                                                                                                                                                                                                                                                                                                                                                                                                                                                                                                                                                                                                                                                                                                                                                                                                                                                                                                                                                                                                                                                                                                                                                                                                                                                                                                                                                                                                                                                                                                                                                                                                                                                                                                                                                                                                                                                                                                                                                                                                                                                                                                                                                                                                                                                                                                                                                                                                                                                                                                                                                                                                                                                                                                                                                                                                                                                                                                                                                                                                                                                                                                                                                                                                                                                                                                                                                                                                                                                                                                                                                                                                                                                                                                                                                                                                               -1.5707963 -1.22464679915e-16 3.14159265359                                                                                                                                                                                                                                                                                                                                                                                                                                                                                                                                                                                                                                                                                                                                                                                                                                                                                                                                                                                                                                                                                                                                                                                                                                                                                                                                                                                                                                                                                                                                                                                                                                                                                                                                                                                                                                                                                                                                                                                                                                                                                                                                                                                                                                                                                                                                                                                                                                                                                                                                                                                                                                                                                                                                                                                                                                                                                                                                                                                                                                                                                                                                                                                                                                                                                                                                                                                                                                                                                                                                                                                                                                                                                                                                                                                                                                                                                                                                                                                                                                                                                                                                                                                                                                                                                                                                                                                                                                                                                                                                                                                                                                                                                                                                                                                                                                                                                                                                                                                                                                                                                                                                                                                                                                                                                                                                                                                                                                                                                                                                                                                                                                                                                                                                                                                                                                                                                                                                                                                                                                                                                                                                                                                                                                                                                                                                                                                                                                                                                                                                                                                                                                                                                                                                                                                                                                                                                                                                                                                                                                                                                                                                                                                                                                                                                                                                                                                                                                                                                                                                                                                                                                                                                                                                                                                                                                                                                                                                                                                                                                                                                                                                                                                                                                                                                                                                                                                                                                                                                                                                                                                                                                                                                                                                                                                                                                                                                                                                                                                                                                                                                                                                                                                                                                                                                                                                                                                                                                                                                                                                                                                                                                                                                                                                                                                                                                                                                                                                                                                                                                                                                                                                                                                                                                                                                                                                                                                                                                                                                                                                                                                                                                                                                                                                                                                                                                                                                                                                                                                                                                                                                                                                                                                                                                                                                                                                                                                                                                                                                                                                                                                                                                                                                                                                                                                                                                                                                                                                                                                                                                                                                                                                                                                                                                                                                                                                                                                                                                                                                                                                                                                                                                                                                                                                           " />
  </joint>
  <link name="base_link">
    <inertial>
      <origin xyz="0.056828169263075 -4.14000490374386E-18 -0.0117288385505833" rpy="0 0 0" />
      <mass value="1.01805130240541" />
      <inertia ixx="0.000223500567511372" ixy="-5.03669428440763E-21" ixz="1.56877722524815E-05" iyy="0.00362147977855399" iyz="2.48425009701901E-21" izz="0.00380745681488709" />
    </inertial>
    <visual>
      <origin xyz="0 0 0" rpy="0 0 0" />
      <geometry>
        <mesh filename="meshes/base_link.STL" />
      </geometry>
      <material name="">
        <color rgba="0.650980392156863 0.619607843137255 0.588235294117647 1" />
      </material>
    </visual>
    <collision>
      <origin xyz="0 0 0" rpy="0 0 0" />
      <geometry>
        <mesh filename="meshes/base_link.STL" />
      </geometry>
    </collision>
  </link>
  <link name="base_link_2">
    <inertial>
      <origin xyz="-0.00158445661415119 6.78094517637425E-19 0.018316845778373" rpy="0 0 0" />
      <mass value="0.0390355310553479" />
      <inertia ixx="1.34883319076031E-05" ixy="3.10257279915433E-22" ixz="4.13353792795213E-07" iyy="1.28963362932004E-05" iyz="1.25797608931366E-21" izz="1.19741642621157E-05" />
    </inertial>
    <visual>
      <origin xyz="0 0 0" rpy="0 0 0" />
      <geometry>
        <mesh filename="meshes/base_link_2.STL" />
      </geometry>
      <material name="">
        <color rgba="0.647058823529412 0.619607843137255 0.588235294117647 1" />
      </material>
    </visual>
    <collision>
      <origin xyz="0 0 0" rpy="0 0 0" />
      <geometry>
        <mesh filename="meshes/base_link_2.STL" />
      </geometry>
    </collision>
  </link>
  <joint name="base_rotate" type="fixed">
    <origin xyz="0.15744562646538 0 -0.019" rpy="3.14159265358979 0 0" />
    <parent link="base_link" />
    <child link="base_link_2" />
    <axis xyz="0 0 0" />
  </joint>
  <link name="base_link_3">
    <inertial>
      <origin xyz="1.73472347597681E-18 6.93889390390723E-18 -0.000499999999999973" rpy="0 0 0" />
      <mass value="1.25663706143592E-05" />
      <inertia ixx="1.36135681655558E-11" ixy="0" ixz="-2.42841104008608E-44" iyy="1.36135681655558E-11" iyz="3.74283737707913E-44" izz="2.51327412287184E-11" />
    </inertial>
    <visual>
      <origin xyz="0 0 0" rpy="0 0 0" />
      <geometry>
        <mesh filename="meshes/base_link_3.STL" />
      </geometry>
      <material name="">
        <color rgba="1 1 1 1" />
      </material>
    </visual>
    <collision>
      <origin xyz="0 0 0" rpy="0 0 0" />
      <geometry>
        <mesh filename="meshes/base_link_3.STL" />
      </geometry>
    </collision>
  </link>
  <joint name="xuanzhuan_jizuo" type="fixed">
    <origin xyz="-0.014 0 0.025" rpy="-1.5707963267949 0 -1.5707963267949" />
    <parent link="base_link_2" />
    <child link="base_link_3" />
    <axis xyz="0 0 0" />
  </joint>
  <joint name="base_tail_to_shovel_base" type="revolute">
    <origin xyz="0 0 0" rpy="3.14159265358979 0 0" />
    <parent link="base_link_3" />
    <child link="shovel_base_link" />
    <axis xyz="0 0 1" />
    <limit lower="-3.14159265358979" upper="3.14159265358979" effort="10" velocity="1" />
  </joint>
  <link name="shovel_base_link">
    <inertial>
      <origin xyz="0.0016245 -1.3997E-06 -0.092921" rpy="0 0 0" />
      <mass value="0.5793" />
      <inertia ixx="0.0043222" ixy="1.5225E-08" ixz="0.00026644" iyy="0.0043066" iyz="2.8511E-08" izz="0.00024905" />
    </inertial>
    <visual>
      <origin xyz="0 0 0" rpy="0 0 0" />
      <geometry>
        <mesh filename="meshes/shovel_base_link.STL" />
      </geometry>
      <material name="">
        <color rgba="1 1 1 1" />
      </material>
    </visual>
    <collision>
      <origin xyz="0 0 0" rpy="0 0 0" />
      <geometry>
        <mesh filename="meshes/shovel_base_link.STL" />
      </geometry>
    </collision>
  </link>
  <link name="shovel_forward_link">
    <inertial>
      <origin xyz="6.9389E-18 -0.00029192 -5E-05" rpy="0 0 0" />
      <mass value="1.0569E-08" />
      <inertia ixx="1.2139E-16" ixy="5.5475E-30" ixz="-1.6941E-30" iyy="1.1144E-16" iyz="8.659E-31" izz="2.1522E-16" />
    </inertial>
    <visual>
      <origin xyz="0 0 0" rpy="0 0 0" />
      <geometry>
        <mesh filename="meshes/shovel_forward_link.STL" />
      </geometry>
      <material name="">
        <color rgba="1 1 1 1" />
      </material>
    </visual>
    <collision>
      <origin xyz="0 0 0" rpy="0 0 0" />
      <geometry>
        <mesh filename="meshes/shovel_forward_link.STL" />
      </geometry>
    </collision>
  </link>
  <joint name="shovel_forward_frame" type="fixed">
    <origin xyz="0.077109 0 -0.33132" rpy="-0.95993 -1.04E-05 -1.5708" />
    <parent link="shovel_base_link" />
    <child link="shovel_forward_link" />
    <axis xyz="0 0 0" />
  </joint>
  <link name="shovel_left_link">
    <inertial>
      <origin xyz="0.0047418 -6.6562E-05 -0.00025" rpy="0 0 0" />
      <mass value="4.7079E-05" />
      <inertia ixx="1.3667E-09" ixy="-9.8037E-12" ixz="2.1476E-25" iyy="1.3427E-10" iyz="-6.527E-25" izz="1.499E-09" />
    </inertial>
    <visual>
      <origin xyz="0 0 0" rpy="0 0 0" />
      <geometry>
        <mesh filename="meshes/shovel_left_link.STL" />
      </geometry>
      <material name="">
        <color rgba="1 1 1 1" />
      </material>
    </visual>
    <collision>
      <origin xyz="0 0 0" rpy="0 0 0" />
      <geometry>
        <mesh filename="meshes/shovel_left_link.STL" />
      </geometry>
    </collision>
  </link>
  <joint name="shovel_left_frame" type="fixed">
    <origin xyz="0.0046013 0.07 -0.22707" rpy="-0.95993 0 -1.5708" />
    <parent link="shovel_base_link" />
    <child link="shovel_left_link" />
    <axis xyz="0 0 0" />
  </joint>
  <link name="shovel_right_link">
    <inertial>
      <origin xyz="-0.0047576 -3.7843E-05 -0.00025" rpy="0 0 0" />
      <mass value="4.7079E-05" />
      <inertia ixx="1.3667E-09" ixy="9.8037E-12" ixz="-1.1391E-25" iyy="1.3427E-10" iyz="3.3087E-24" izz="1.499E-09" />
    </inertial>
    <visual>
      <origin xyz="0 0 0" rpy="0 0 0" />
      <geometry>
        <mesh filename="meshes/shovel_right_link.STL" />
      </geometry>
      <material name="">
        <color rgba="1 1 1 1" />
      </material>
    </visual>
    <collision>
      <origin xyz="0 0 0" rpy="0 0 0" />
      <geometry>
        <mesh filename="meshes/shovel_right_link.STL" />
      </geometry>
    </collision>
  </link>
  <joint name="shovel_right_frame" type="fixed">
    <origin xyz="0.0046277 -0.069975 -0.22711" rpy="-0.95993 0 -1.5708" />
    <parent link="shovel_base_link" />
    <child link="shovel_right_link" />
    <axis xyz="0 0 0" />
  </joint>
  <link name="shovel_surface_center_link">
    <inertial>
      <origin xyz="0 0 0" rpy="0 0 0" />
      <mass value="1e-08" />
      <inertia ixx="1e-12" ixy="0" ixz="0" iyy="1e-12" iyz="0" izz="1e-12" />
    </inertial>
  </link>
  <joint name="shovel_surface_center_frame" type="fixed">
    <origin xyz="0.0287793333333 0.00000833333333 -0.261833333333" rpy="-0.95993 0 -1.5708" />
    <parent link="shovel_base_link" />
    <child link="shovel_surface_center_link" />
    <axis xyz="0 0 0" />
  </joint>
  <joint name="base_jizuo_square_place" type="fixed">
    <parent link="base_jizuo" />
    <child link="base_jizuo_base_ur10_with_dizuo" />
    <origin xyz="-0.78172 -0.025653 1.1638" rpy="3.1416 0 -1.5708" />
  </joint>
  <joint name="base_jizuo-ur10" type="fixed">
    <parent link="base_jizuo_base_ur10_with_dizuo" />
    <child link="ur10" />
    <origin xyz="0 0 0" rpy=" 0 0 0" />
  </joint>
  <joint name="base_jizuo_to_block_with_basin_frame" type="fixed">
    <parent link="base_jizuo" />
    <child link="block_with_basin_frame" />
    <origin xyz="-1.830000 0.000000 0.000000" rpy="0.000000000000 0.000000000000 3.141592653590" />
  </joint>
  <joint name="block_frame_to_base" type="fixed">
    <parent link="block_with_basin_frame" />
    <child link="block_basin_base_link" />
    <origin xyz="0 0 0" rpy="0 0 0" />
  </joint>
  <joint name="block_joint" type="fixed">
    <parent link="block_basin_base_link" />
    <child link="block_basin_block" />
    <origin xyz="0 0 0.125" rpy="0 0 0" />
  </joint>
  <joint name="basin_back_joint" type="fixed">
    <parent link="block_basin_block" />
    <child link="block_basin_back_wall" />
    <origin xyz="-0.135 -0.2485 0.425" rpy="0 0 0" />
  </joint>
</robot>
