<?xml version="1.0" encoding="utf-8"?>
<robot name="world_scene">
  <!-- Combined scene for later pose tuning.
       Adjust only the two frame joints below to move each object as a whole. -->

  <material name="block_gray">
    <color rgba="0.6 0.6 0.6 0.8"/>
  </material>
  <material name="basin_blue">
    <color rgba="0.2 0.4 0.8 0.7"/>
  </material>
  <material name="mat_sensor_shovel">
    <color rgba="0.79216078 0.81961176 0.92941569 1.00000000"/>
  </material>
  <material name="mat_shovel_tcp">
    <color rgba="1.00000000 1.00000000 1.00000000 1.00000000"/>
  </material>
  <material name="mat_base_jizuo">
    <color rgba="1.00000000 1.00000000 1.00000000 1.00000000"/>
  </material>
  <material name="mat_base_ur10_with_dizuo">
    <color rgba="1.00000000 1.00000000 1.00000000 1.00000000"/>
  </material>
  <material name="SWMaterial-0">
    <color rgba="0.22353333 0.22353333 0.22353333 1.00000000"/>
  </material>
  <material name="SWMaterial-1">
    <color rgba="0.39216078 0.54118039 0.63921961 1.00000000"/>
  </material>
  <material name="SWMaterial-2">
    <color rgba="0.46274902 0.46274902 0.46274902 1.00000000"/>
  </material>
  <material name="SWMaterial-3">
    <color rgba="0.65490588 0.65490588 0.65490588 1.00000000"/>
  </material>
  <material name="SWMaterial-4">
    <color rgba="0.07843529 0.07843529 0.07843529 1.00000000"/>
  </material>
  <material name="SWMaterial-0_001">
    <color rgba="0.22353333 0.22353333 0.22353333 1.00000000"/>
  </material>
  <material name="SWMaterial-1_001">
    <color rgba="0.39216078 0.54118039 0.63921961 1.00000000"/>
  </material>
  <material name="SWMaterial-2_001">
    <color rgba="0.37255294 0.37255294 0.37255294 1.00000000"/>
  </material>
  <material name="SWMaterial-0_002">
    <color rgba="0.22353333 0.22353333 0.22353333 1.00000000"/>
  </material>
  <material name="SWMaterial-1_002">
    <color rgba="0.39216078 0.54118039 0.63921961 1.00000000"/>
  </material>
  <material name="SWMaterial-2_002">
    <color rgba="0.46274902 0.46274902 0.46274902 1.00000000"/>
  </material>
  <material name="SWMaterial-2_003">
    <color rgba="0.46274902 0.46274902 0.46274902 1.00000000"/>
  </material>

  <link name="world"/>
  <link name="block_with_basin_frame"/>
  <link name="base_jizuo">
    <visual>
      <origin xyz="0 0 0" rpy="0 0 0" />
      <geometry>
        <mesh filename="meshes/base_link_world_jizuo.STL" />
      </geometry>
      <material name="mat_base_jizuo"/>
    </visual>
    <collision>
      <origin xyz="0 0 0" rpy="0 0 0" />
      <geometry>
        <mesh filename="meshes/base_link_world_jizuo.STL" />
      </geometry>
    </collision>
    <inertial>
      <origin xyz="-1.8696 -0.046752 0.24794" rpy="0 0 0" />
      <mass value="1499.1" />
      <inertia ixx="1126.8" ixy="-0.036857" ixz="0.0017432" iyy="2608.5" iyz="-18.236" izz="3614.6" />
    </inertial>
  </link>

  <!-- Edit this joint to move the block + basin as one object. -->
  <joint name="world_to_block_with_basin_frame" type="fixed">
    <parent link="base_jizuo"/>
    <child link="block_with_basin_frame"/>
    <origin xyz="0 0 0" rpy="0 0 0"/>
  </joint>

  <!-- Full assembly root from assembly.urdf.xacro. -->
  <joint name="world_to_base_jizuo" type="fixed">
    <parent link="world"/>
    <child link="base_jizuo"/>
    <origin xyz="0 0 0" rpy="0 0 0"/>
  </joint>

  <!-- ===== Block with basin ===== -->
  <link name="block_basin_base_link"/>

  <link name="block_basin_block">
    <visual>
      <geometry>
        <box size="1.0 1.0 0.25"/>
      </geometry>
      <material name="block_gray"/>
    </visual>
    <collision>
      <geometry>
        <box size="1.0 1.0 0.25"/>
      </geometry>
    </collision>
  </link>

  <link name="block_basin_bottom">
    <visual>
      <geometry>
        <box size="0.37 0.50 0.003"/>
      </geometry>
      <material name="basin_blue"/>
    </visual>
    <collision>
      <geometry>
        <box size="0.37 0.50 0.003"/>
      </geometry>
    </collision>
  </link>

  <link name="block_basin_front_wall">
    <visual>
      <geometry>
        <box size="0.37 0.003 0.18"/>
      </geometry>
      <material name="basin_blue"/>
    </visual>
    <collision>
      <geometry>
        <box size="0.37 0.003 0.18"/>
      </geometry>
    </collision>
  </link>

  <link name="block_basin_back_wall">
    <visual>
      <geometry>
        <box size="0.37 0.003 0.18"/>
      </geometry>
      <material name="basin_blue"/>
    </visual>
    <collision>
      <geometry>
        <box size="0.37 0.003 0.18"/>
      </geometry>
    </collision>
  </link>

  <link name="block_basin_left_wall">
    <visual>
      <geometry>
        <box size="0.003 0.494 0.18"/>
      </geometry>
      <material name="basin_blue"/>
    </visual>
    <collision>
      <geometry>
        <box size="0.003 0.494 0.18"/>
      </geometry>
    </collision>
  </link>

  <link name="block_basin_right_wall">
    <visual>
      <geometry>
        <box size="0.003 0.494 0.18"/>
      </geometry>
      <material name="basin_blue"/>
    </visual>
    <collision>
      <geometry>
        <box size="0.003 0.494 0.18"/>
      </geometry>
    </collision>
  </link>

  <joint name="block_frame_to_base" type="fixed">
    <parent link="block_with_basin_frame"/>
    <child link="block_basin_base_link"/>
    <origin xyz="0 0 0" rpy="0 0 0"/>
  </joint>

  <joint name="block_joint" type="fixed">
    <parent link="block_basin_base_link"/>
    <child link="block_basin_block"/>
    <origin xyz="0 0 0.125" rpy="0 0 0"/>
  </joint>

  <joint name="basin_base_joint" type="fixed">
    <parent link="block_basin_base_link"/>
    <child link="block_basin_bottom"/>
    <origin xyz="-0.135 0 0.25" rpy="0 0 0"/>
  </joint>

  <joint name="basin_front_joint" type="fixed">
    <parent link="block_basin_bottom"/>
    <child link="block_basin_front_wall"/>
    <origin xyz="0 0.2485 0.09" rpy="0 0 0"/>
  </joint>

  <joint name="basin_back_joint" type="fixed">
    <parent link="block_basin_bottom"/>
    <child link="block_basin_back_wall"/>
    <origin xyz="0 -0.2485 0.09" rpy="0 0 0"/>
  </joint>

  <joint name="basin_left_joint" type="fixed">
    <parent link="block_basin_bottom"/>
    <child link="block_basin_left_wall"/>
    <origin xyz="-0.1835 0 0.09" rpy="0 0 0"/>
  </joint>

  <joint name="basin_right_joint" type="fixed">
    <parent link="block_basin_bottom"/>
    <child link="block_basin_right_wall"/>
    <origin xyz="0.1835 0 0.09" rpy="0 0 0"/>
  </joint>

  <!-- ===== UR10 with shovel ===== -->
  <link name="base_jizuo_base_ur10_with_dizuo">
    <visual>
      <origin xyz="0 0 0" rpy="0 0 0" />
      <geometry>
        <mesh filename="meshes/base_ur10_with_dizuo.STL" />
      </geometry>
      <material name="mat_base_ur10_with_dizuo"/>
    </visual>
    <collision>
      <origin xyz="0 0 0" rpy="0 0 0" />
      <geometry>
        <mesh filename="meshes/base_ur10_with_dizuo.STL" />
      </geometry>
    </collision>
    <inertial>
      <origin xyz="0 0 0.005" rpy="0 0 0" />
      <mass value="0.225" />
      <inertia ixx="0.0004237" ixy="0" ixz="0" iyy="0.0004237" iyz="0" izz="0.0008437" />
    </inertial>
  </link>

  <link name="sensor_shovel">
    <visual>
      <origin xyz="0 0 0" rpy="0 0 0" />
      <geometry>
        <mesh filename="meshes/base_link.STL" />
      </geometry>
      <material name="mat_sensor_shovel"/>
    </visual>
    <collision>
      <origin xyz="0 0 0" rpy="0 0 0" />
      <geometry>
        <mesh filename="meshes/base_link.STL" />
      </geometry>
    </collision>
    <inertial>
      <origin xyz="-0.11585 0.0005511 0.051294" rpy="0 0 0" />
      <mass value="2.3" />
      <inertia ixx="0.0005331" ixy="0.0002664" ixz="0.0000158" iyy="0.0080026" iyz="0" izz="0.0082034" />
    </inertial>
  </link>

  <link name="sensor_shovel_tcp">
    <visual>
      <origin xyz="0 0 0" rpy="0 0 0" />
      <geometry>
        <mesh filename="meshes/shovel_tcp.STL" />
      </geometry>
      <material name="mat_shovel_tcp"/>
    </visual>
    <collision>
      <origin xyz="0 0 0" rpy="0 0 0" />
      <geometry>
        <mesh filename="meshes/shovel_tcp.STL" />
      </geometry>
    </collision>
    <inertial>
      <origin xyz="0 -0.0002919 -0.00005" rpy="0 0 0" />
      <mass value="0" />
      <inertia ixx="0" ixy="0" ixz="0" iyy="0" iyz="0" izz="0" />
    </inertial>
  </link>

  <link name="ur10">
    <visual>
      <origin xyz="0 0 0" rpy="0 0 0" />
      <geometry>
        <mesh filename="meshes/base.dae" />
      </geometry>
      <material name="SWMaterial-2_001"/>
    </visual>
    <collision>
      <origin xyz="0 0 0.019" rpy="0 0 0" />
      <geometry>
        <cylinder radius="0.075" length="0.038" />
      </geometry>
    </collision>
    <inertial>
      <origin xyz="0 0 0" rpy="0 0 0" />
      <mass value="4" />
      <inertia ixx="0.0061063" ixy="0" ixz="0" iyy="0.0061063" iyz="0" izz="0.01125" />
    </inertial>
  </link>

  <link name="ur10_shoulder">
    <visual>
      <origin xyz="0 0 0" rpy="0 0 0" />
      <geometry>
        <mesh filename="meshes/shoulder.dae" />
      </geometry>
      <material name="SWMaterial-0"/>
      <material name="SWMaterial-1"/>
      <material name="SWMaterial-2"/>
    </visual>
    <collision>
      <origin xyz="0 0 0" rpy="0 0 0" />
      <geometry>
        <cylinder radius="0.075" length="0.177" />
      </geometry>
    </collision>
    <inertial>
      <origin xyz="0 0 0" rpy="0 0 0" />
      <mass value="7.778" />
      <inertia ixx="0.0314743" ixy="0" ixz="0" iyy="0.0314743" iyz="0" izz="0.0218756" />
    </inertial>
  </link>

  <link name="ur10_upper_arm">
    <visual>
      <origin xyz="0 0 0" rpy="0 0 0" />
      <geometry>
        <mesh filename="meshes/upperarm.dae" />
      </geometry>
      <material name="SWMaterial-0"/>
      <material name="SWMaterial-1"/>
      <material name="SWMaterial-2"/>
      <material name="SWMaterial-3"/>
    </visual>
    <collision>
      <origin xyz="0 -0.045 0" rpy="1.5707 0 0" />
      <geometry>
        <cylinder radius="0.075" length="0.177" />
      </geometry>
    </collision>
    <collision>
      <origin xyz="0 -0.0436 0.32" rpy="0 0 1.5707" />
      <geometry>
        <cylinder radius="0.058" length="0.461" />
      </geometry>
    </collision>
    <collision>
      <origin xyz="0 -0.04 0.613" rpy="1.5707 0 0" />
      <geometry>
        <cylinder radius="0.058" length="0.129" />
      </geometry>
    </collision>
    <inertial>
      <origin xyz="0 0 0.306" rpy="0 0 0" />
      <mass value="12.93" />
      <inertia ixx="0.421754" ixy="0" ixz="0" iyy="0.421754" iyz="0" izz="0.0363656" />
    </inertial>
  </link>

  <link name="ur10_forearm">
    <visual>
      <origin xyz="0 0 0" rpy="0 0 0" />
      <geometry>
        <mesh filename="meshes/forearm.dae" />
      </geometry>
      <material name="SWMaterial-0"/>
      <material name="SWMaterial-1"/>
      <material name="SWMaterial-2"/>
      <material name="SWMaterial-3"/>
      <material name="SWMaterial-4"/>
    </visual>
    <collision>
      <origin xyz="0 0 0.001" rpy="1.5707 0 0" />
      <geometry>
        <cylinder radius="0.058" length="0.136" />
      </geometry>
    </collision>
    <collision>
      <origin xyz="0 0 0.305" rpy="0 0 1.5707" />
      <geometry>
        <cylinder radius="0.045" length="0.447" />
      </geometry>
    </collision>
    <collision>
      <origin xyz="0 0.001 0.5735" rpy="1.5707 0 0" />
      <geometry>
        <cylinder radius="0.045" length="0.119" />
      </geometry>
    </collision>
    <inertial>
      <origin xyz="0 0 0.28615" rpy="0 0 0" />
      <mass value="3.87" />
      <inertia ixx="0.11107" ixy="0" ixz="0" iyy="0.11107" iyz="0" izz="0.0108844" />
    </inertial>
  </link>

  <link name="ur10_wrist_1">
    <visual>
      <origin xyz="0 0 0" rpy="0 0 0" />
      <geometry>
        <mesh filename="meshes/wrist1.dae" />
      </geometry>
      <material name="SWMaterial-0_001"/>
      <material name="SWMaterial-1_001"/>
      <material name="SWMaterial-2_001"/>
    </visual>
    <collision>
      <origin xyz="0 0.115 0.0025" rpy="0 0 0" />
      <geometry>
        <cylinder radius="0.0455" length="0.119" />
      </geometry>
    </collision>
    <inertial>
      <origin xyz="0 0 0" rpy="0 0 0" />
      <mass value="1.96" />
      <inertia ixx="0.0051082" ixy="0" ixz="0" iyy="0.0051082" iyz="0" izz="0.0055125" />
    </inertial>
  </link>

  <link name="ur10_wrist_2">
    <visual>
      <origin xyz="0 0 0" rpy="0 0 0" />
      <geometry>
        <mesh filename="meshes/wrist2.dae" />
      </geometry>
      <material name="SWMaterial-0_002"/>
      <material name="SWMaterial-1_002"/>
      <material name="SWMaterial-2_002"/>
    </visual>
    <collision>
      <origin xyz="0 0.002 0.11659" rpy="1.5707 0 0" />
      <geometry>
        <cylinder radius="0.0455" length="0.119" />
      </geometry>
    </collision>
    <inertial>
      <origin xyz="0 0 0" rpy="0 0 0" />
      <mass value="1.96" />
      <inertia ixx="0.0051082" ixy="0" ixz="0" iyy="0.0051082" iyz="0" izz="0.0055125" />
    </inertial>
  </link>

  <link name="ur10_wrist_3">
    <visual>
      <origin xyz="0 0 0" rpy="0 0 0" />
      <geometry>
        <mesh filename="meshes/wrist3.dae" />
      </geometry>
      <material name="SWMaterial-2_003"/>
    </visual>
    <collision>
      <origin xyz="0 0.0765 0" rpy="1.5707 0 0" />
      <geometry>
        <cylinder radius="0.045" length="0.031" />
      </geometry>
    </collision>
    <inertial>
      <origin xyz="0 0 0" rpy="0 0 0" />
      <mass value="0.202" />
      <inertia ixx="0.0005265" ixy="0" ixz="0" iyy="0.0005265" iyz="0" izz="0.0005681" />
    </inertial>
  </link>

  <joint name="base_jizuo_square_place" type="fixed">
    <parent link="base_jizuo"/>
    <child link="base_jizuo_base_ur10_with_dizuo"/>
    <origin xyz="-0.78172 -0.025653 1.1638" rpy="3.1416 0 -1.5708"/>
  </joint>

  <joint name="base_jizuo_to_ur10" type="fixed">
    <parent link="base_jizuo_base_ur10_with_dizuo"/>
    <child link="ur10"/>
    <origin xyz="0 0 0" rpy="0 0 0"/>
  </joint>

  <joint name="sensor_shovel_tcp_fixed" type="fixed">
    <parent link="sensor_shovel" />
    <child link="sensor_shovel_tcp" />
    <origin xyz="-0.47377 0.077109 0.0733" rpy="-1.5708 1.5708 -0.61087" />
  </joint>

  <joint name="ur10_shoulder_pan" type="revolute">
    <parent link="ur10" />
    <child link="ur10_shoulder" />
    <origin xyz="0 0 0.1273" rpy="0 0 0" />
    <axis xyz="0 0 1" />
    <limit lower="-6.28319" upper="6.28319" effort="330" velocity="2.16" />
  </joint>

  <joint name="ur10_shoulder_lift" type="revolute">
    <parent link="ur10_shoulder" />
    <child link="ur10_upper_arm" />
    <origin xyz="0 0.220941 0" rpy="0 1.57079 0" />
    <axis xyz="0 1 0" />
    <limit lower="-6.28319" upper="6.28319" effort="330" velocity="2.16" />
  </joint>

  <joint name="ur10_elbow" type="revolute">
    <parent link="ur10_upper_arm" />
    <child link="ur10_forearm" />
    <origin xyz="-0.0000039 -0.1719 0.612" rpy="0 0 0" />
    <axis xyz="0 1 0" />
    <limit lower="-6.28319" upper="6.28319" effort="150" velocity="3.15" />
  </joint>

  <joint name="ur10_wrist_1_joint" type="revolute">
    <parent link="ur10_forearm" />
    <child link="ur10_wrist_1" />
    <origin xyz="-0.0000036 0 0.5723" rpy="0 1.5707895 0.0000027" />
    <axis xyz="0 1 0" />
    <limit lower="-6.28319" upper="6.28319" effort="54" velocity="3.2" />
  </joint>

  <joint name="ur10_wrist_2_joint" type="revolute">
    <parent link="ur10_wrist_1" />
    <child link="ur10_wrist_2" />
    <origin xyz="0.0000003 0.1149 0.0000003" rpy="0 0 0" />
    <axis xyz="0 0 -1" />
    <limit lower="-6.28319" upper="6.28319" effort="54" velocity="3.2" />
  </joint>

  <joint name="ur10_wrist_3_joint" type="revolute">
    <parent link="ur10_wrist_2" />
    <child link="ur10_wrist_3" />
    <origin xyz="0 -0.0000003 0.1157" rpy="0 0 0" />
    <axis xyz="0 1 0" />
    <limit lower="-6.28319" upper="6.28319" effort="54" velocity="3.2" />
  </joint>

  <joint name="ur10_sensor_shovel" type="fixed">
    <parent link="ur10_wrist_3" />
    <child link="sensor_shovel" />
    <origin xyz="0 0.09 0" rpy="-1.5707963 0 0" />
  </joint>
</robot>
