<?xml version="1.0" encoding="utf-8"?>
<!--Merged from base_with_ur10 and shovel_with_3frame. base_link_3 is fixed to shovel_base_link.-->
<robot name="shovel_rotate">
  <link name="base_link">
    <inertial>
      <origin xyz="0.056828169263075 -4.14000490374386E-18 -0.0117288385505833" rpy="0 0 0" />
      <mass value="1.01805130240541" />
      <inertia ixx="0.000223500567511372" ixy="-5.03669428440763E-21" ixz="1.56877722524815E-05" iyy="0.00362147977855399" iyz="2.48425009701901E-21" izz="0.00380745681488709" />
    </inertial>
    <visual>
      <origin xyz="0 0 0" rpy="0 0 0" />
      <geometry>
        <mesh filename="package://shovel_rotate/meshes/base_link.STL" />
      </geometry>
      <material name="">
        <color rgba="0.650980392156863 0.619607843137255 0.588235294117647 1" />
      </material>
    </visual>
    <collision>
      <origin xyz="0 0 0" rpy="0 0 0" />
      <geometry>
        <mesh filename="package://shovel_rotate/meshes/base_link.STL" />
      </geometry>
    </collision>
  </link>
  <link name="base_link_2">
    <inertial>
      <origin xyz="-0.00158445661415119 6.78094517637425E-19 0.018316845778373" rpy="0 0 0" />
      <mass value="0.0390355310553479" />
      <inertia ixx="1.34883319076031E-05" ixy="3.10257279915433E-22" ixz="4.13353792795213E-07" iyy="1.28963362932004E-05" iyz="1.25797608931366E-21" izz="1.19741642621157E-05" />
    </inertial>
    <visual>
      <origin xyz="0 0 0" rpy="0 0 0" />
      <geometry>
        <mesh filename="package://shovel_rotate/meshes/base_link_2.STL" />
      </geometry>
      <material name="">
        <color rgba="0.647058823529412 0.619607843137255 0.588235294117647 1" />
      </material>
    </visual>
    <collision>
      <origin xyz="0 0 0" rpy="0 0 0" />
      <geometry>
        <mesh filename="package://shovel_rotate/meshes/base_link_2.STL" />
      </geometry>
    </collision>
  </link>
  <joint name="base_rotate" type="fixed">
    <origin xyz="0.15744562646538 0 -0.019" rpy="3.14159265358979 0 0" />
    <parent link="base_link" />
    <child link="base_link_2" />
    <axis xyz="0 0 0" />
  </joint>
  <link name="base_link_3">
    <inertial>
      <origin xyz="1.73472347597681E-18 6.93889390390723E-18 -0.000499999999999973" rpy="0 0 0" />
      <mass value="1.25663706143592E-05" />
      <inertia ixx="1.36135681655558E-11" ixy="0" ixz="-2.42841104008608E-44" iyy="1.36135681655558E-11" iyz="3.74283737707913E-44" izz="2.51327412287184E-11" />
    </inertial>
    <visual>
      <origin xyz="0 0 0" rpy="0 0 0" />
      <geometry>
        <mesh filename="package://shovel_rotate/meshes/base_link_3.STL" />
      </geometry>
      <material name="">
        <color rgba="1 1 1 1" />
      </material>
    </visual>
    <collision>
      <origin xyz="0 0 0" rpy="0 0 0" />
      <geometry>
        <mesh filename="package://shovel_rotate/meshes/base_link_3.STL" />
      </geometry>
    </collision>
  </link>
  <joint name="xuanzhuan_jizuo" type="fixed">
    <origin xyz="-0.014 0 0.025" rpy="-1.5707963267949 0 -1.5707963267949" />
    <parent link="base_link_2" />
    <child link="base_link_3" />
    <axis xyz="0 0 0" />
  </joint>
  <joint name="base_tail_to_shovel_base" type="revolute">
    <origin xyz="0 0 0" rpy="3.14159265358979 0 0" />
    <parent link="base_link_3" />
    <child link="shovel_base_link" />
    <axis xyz="0 0 1" />
    <limit lower="-3.14159265358979" upper="3.14159265358979" effort="10" velocity="1" />
  </joint>
  <link name="shovel_base_link">
    <inertial>
      <origin xyz="0.0016245 -1.3997E-06 -0.092921" rpy="0 0 0" />
      <mass value="0.5793" />
      <inertia ixx="0.0043222" ixy="1.5225E-08" ixz="0.00026644" iyy="0.0043066" iyz="2.8511E-08" izz="0.00024905" />
    </inertial>
    <visual>
      <origin xyz="0 0 0" rpy="0 0 0" />
      <geometry>
        <mesh filename="package://shovel_rotate/meshes/shovel_base_link.STL" />
      </geometry>
      <material name="">
        <color rgba="1 1 1 1" />
      </material>
    </visual>
    <collision>
      <origin xyz="0 0 0" rpy="0 0 0" />
      <geometry>
        <mesh filename="package://shovel_rotate/meshes/shovel_base_link.STL" />
      </geometry>
    </collision>
  </link>
  <link name="shovel_forward_link">
    <inertial>
      <origin xyz="6.9389E-18 -0.00029192 -5E-05" rpy="0 0 0" />
      <mass value="1.0569E-08" />
      <inertia ixx="1.2139E-16" ixy="5.5475E-30" ixz="-1.6941E-30" iyy="1.1144E-16" iyz="8.659E-31" izz="2.1522E-16" />
    </inertial>
    <visual>
      <origin xyz="0 0 0" rpy="0 0 0" />
      <geometry>
        <mesh filename="package://shovel_rotate/meshes/shovel_forward_link.STL" />
      </geometry>
      <material name="">
        <color rgba="1 1 1 1" />
      </material>
    </visual>
    <collision>
      <origin xyz="0 0 0" rpy="0 0 0" />
      <geometry>
        <mesh filename="package://shovel_rotate/meshes/shovel_forward_link.STL" />
      </geometry>
    </collision>
  </link>
  <joint name="shovel_forward_frame" type="fixed">
    <origin xyz="0.077109 0 -0.33132" rpy="-0.95993 -1.04E-05 -1.5708" />
    <parent link="shovel_base_link" />
    <child link="shovel_forward_link" />
    <axis xyz="0 0 0" />
  </joint>
  <link name="shovel_left_link">
    <inertial>
      <origin xyz="0.0047418 -6.6562E-05 -0.00025" rpy="0 0 0" />
      <mass value="4.7079E-05" />
      <inertia ixx="1.3667E-09" ixy="-9.8037E-12" ixz="2.1476E-25" iyy="1.3427E-10" iyz="-6.527E-25" izz="1.499E-09" />
    </inertial>
    <visual>
      <origin xyz="0 0 0" rpy="0 0 0" />
      <geometry>
        <mesh filename="package://shovel_rotate/meshes/shovel_left_link.STL" />
      </geometry>
      <material name="">
        <color rgba="1 1 1 1" />
      </material>
    </visual>
    <collision>
      <origin xyz="0 0 0" rpy="0 0 0" />
      <geometry>
        <mesh filename="package://shovel_rotate/meshes/shovel_left_link.STL" />
      </geometry>
    </collision>
  </link>
  <joint name="shovel_left_frame" type="fixed">
    <origin xyz="0.0046013 0.07 -0.22707" rpy="-0.95993 0 -1.5708" />
    <parent link="shovel_base_link" />
    <child link="shovel_left_link" />
    <axis xyz="0 0 0" />
  </joint>
  <link name="shovel_right_link">
    <inertial>
      <origin xyz="-0.0047576 -3.7843E-05 -0.00025" rpy="0 0 0" />
      <mass value="4.7079E-05" />
      <inertia ixx="1.3667E-09" ixy="9.8037E-12" ixz="-1.1391E-25" iyy="1.3427E-10" iyz="3.3087E-24" izz="1.499E-09" />
    </inertial>
    <visual>
      <origin xyz="0 0 0" rpy="0 0 0" />
      <geometry>
        <mesh filename="package://shovel_rotate/meshes/shovel_right_link.STL" />
      </geometry>
      <material name="">
        <color rgba="1 1 1 1" />
      </material>
    </visual>
    <collision>
      <origin xyz="0 0 0" rpy="0 0 0" />
      <geometry>
        <mesh filename="package://shovel_rotate/meshes/shovel_right_link.STL" />
      </geometry>
    </collision>
  </link>
  <joint name="shovel_right_frame" type="fixed">
    <origin xyz="0.0046277 -0.069975 -0.22711" rpy="-0.95993 0 -1.5708" />
    <parent link="shovel_base_link" />
    <child link="shovel_right_link" />
    <axis xyz="0 0 0" />
  </joint>
  <link name="shovel_surface_center_link">
    <inertial>
      <origin xyz="0 0 0" rpy="0 0 0" />
      <mass value="1e-08" />
      <inertia ixx="1e-12" ixy="0" ixz="0" iyy="1e-12" iyz="0" izz="1e-12" />
    </inertial>
  </link>
  <joint name="shovel_surface_center_frame" type="fixed">
    <origin xyz="0.0287793333333 0.00000833333333 -0.261833333333" rpy="-0.95993 0 -1.5708" />
    <parent link="shovel_base_link" />
    <child link="shovel_surface_center_link" />
    <axis xyz="0 0 0" />
  </joint>
</robot>
